<?xml version='1.0' encoding='utf-8'?>
  <!-- This URDF was automatically created by SolidWorks to URDF Exporter! Originally created by Stephen Brawner (brawner@gmail.com) 
     Commit Version: 1.6.0-4-g7f85cfe  Build Version: 1.6.7995.38578
     For more information, please see http://wiki.ros.org/sw_urdf_exporter -->
<robot
  name="gp2">
  <mujoco>
        <compiler meshdir="../meshes/" balanceinertia="true" discardvisual="false" fusestatic="false"/>
  </mujoco>

  <link name="base_link">
    <inertial>
      <origin xyz="0 -0.004 0.025" rpy="0 0 0" />
      <mass value="0.987" />
      <inertia ixx="0.006" ixy="0" ixz="0" iyy="0.004" iyz="0" izz="0.003" />
    </inertial>
    <visual>
      <origin xyz="0 0 0" rpy="0 0 0" />
      <geometry>
        <mesh filename="../meshes/base_link.STL" />
      </geometry>
      <material name="">
        <color rgba="0.752941176470588 0.752941176470588 0.752941176470588 1" />
      </material>
    </visual>
    <collision>
      <origin xyz="0 0 0" rpy="0 0 0" />
      <geometry>
        <mesh filename="../meshes/base_link.STL" />
      </geometry>
    </collision>
  </link>

  <!-- Legs -->
  <link name="left_hip_pitch_link">
    <inertial>
      <origin xyz="0.002 0.045 0" rpy="0 0 0" />
      <mass value="0.422" />
      <inertia ixx="0.001" ixy="0" ixz="0" iyy="0.001" iyz="0" izz="0.001" />
    </inertial>
    <visual>
      <origin xyz="0 0 0" rpy="0 0 0" />
      <geometry>
        <mesh filename="../meshes/L_hip_pitch_link.STL" />
      </geometry>
      <material name="">
        <color rgba="0.75294 0.75294 0.75294 1" />
      </material>
    </visual>
    <!-- <collision>
      <origin xyz="0 0 0" rpy="0 0 0" />
      <geometry>
        <mesh filename="../meshes/L_hip_pitch_link.STL" />
      </geometry>
    </collision> -->
  </link>
  <joint name="left_hip_pitch_joint" type="revolute">
    <origin xyz="0 0.0790000000000005 0" rpy="0 0 0" />
    <parent link="base_link" />
    <child link="left_hip_pitch_link" />
    <axis xyz="0 1 0" />
    <limit lower="-2.62" upper="2.62" effort="88" velocity="32"/>
  </joint>
  <link name="left_hip_roll_link">
    <inertial>
      <origin xyz="-0.032 -0.001 -0.078" rpy="0 0 0" />
      <mass value="0.785" />
      <inertia ixx="0.008" ixy="0" ixz="0.002" iyy="0.009" iyz="0" izz="0.002" />
    </inertial>
    <visual>
      <origin xyz="0 0 0" rpy="0 0 0" />
      <geometry>
        <mesh filename="../meshes/L_hip_roll_link.STL" />
      </geometry>
      <material name="">
        <color rgba="0.752941176470588 0.752941176470588 0.752941176470588 1" />
      </material>
    </visual>
    <!-- <collision>
      <origin xyz="0 0 0" rpy="0 0 0" />
      <geometry>
        <mesh filename="../meshes/L_hip_roll_link.STL" />
      </geometry>
    </collision> -->
  </link>
  <joint name="left_hip_roll_joint" type="revolute">
    <origin xyz="0.0365999999999998 0.0499999999999994 0" rpy="0 0 0" />
    <parent link="left_hip_pitch_link" />
    <child link="left_hip_roll_link" />
    <axis xyz="1 0 0" />
    <limit lower="-0.17" upper="3.32" effort="88" velocity="32"/>
  </joint>
  <link name="left_hip_yaw_link">
    <inertial>
      <origin xyz="-0.019 -0.007 -0.08" rpy="0 0 0" />
      <mass value="0.865" />
      <inertia ixx="0.008" ixy="0" ixz="0.002" iyy="0.009" iyz="0" izz="0.002" />
    </inertial>
    <visual>
      <origin xyz="0 0 0" rpy="0 0 0" />
      <geometry>
        <mesh filename="../meshes/L_hip_yaw_link.STL" />
      </geometry>
      <material name="">
        <color rgba="0.752941176470588 0.752941176470588 0.752941176470588 1" />
      </material>
    </visual>
    <!-- <collision>
      <origin xyz="0 0 0" rpy="0 0 0" />
      <geometry>
        <mesh filename="../meshes/L_hip_yaw_link.STL" />
      </geometry>
    </collision> -->
  </link>
  <joint name="left_hip_yaw_joint" type="revolute">
    <origin xyz="-0.0365999999999971 0 -0.156600000000001" rpy="0 0 0" />
    <parent link="left_hip_roll_link" />
    <child link="left_hip_yaw_link" />
    <axis xyz="0 0 1" />
    <limit lower="-2.62" upper="2.62" effort="88" velocity="32"/>
  </joint>
  <link name="left_knee_link">
    <inertial>
      <origin xyz="0.033 -0.041 -0.132" rpy="0 0 0" />
      <mass value="2.033" />
      <inertia ixx="0.058" ixy="0" ixz="0" iyy="0.056" iyz="0" izz="0.011" />
    </inertial>
    <visual>
      <origin xyz="0 0 0" rpy="0 0 0" />
      <geometry>
        <mesh filename="../meshes/L_knee_link.STL" />
      </geometry>
      <material name="">
        <color rgba="0.752941176470588 0.752941176470588 0.752941176470588 1" />
      </material>
    </visual>
    <!-- <collision>
      <origin xyz="0 0 0" rpy="0 0 0" />
      <geometry>
        <mesh filename="../meshes/L_knee_link.STL" />
      </geometry>
    </collision> -->
  </link>
  <joint name="left_knee_joint" type="revolute">
    <origin xyz="-0.0349999999999989 0.0406000000000009 -0.113900000000001" rpy="0 0 0" />
    <parent link="left_hip_yaw_link" />
    <child link="left_knee_link" />
    <axis xyz="0 1 0" />
    <limit lower="-0.17" upper="2.97" effort="139" velocity="20"/>
  </joint>
  <link name="left_ankle_pitch_link">
    <inertial>
      <origin xyz="0 -0.016 0" rpy="0 0 0" />
      <mass value="0.056" />
      <inertia ixx="0.0001" ixy="0" ixz="0" iyy="0.0001" iyz="0" izz="0.0001" />
    </inertial>
    <visual>
      <origin xyz="0 0 0" rpy="0 0 0" />
      <geometry>
        <mesh filename="../meshes/L_ankle_pitch_link.STL" />
      </geometry>
      <material name="">
        <color rgba="0.792156862745098 0.819607843137255 0.929411764705882 1" />
      </material>
    </visual>
    <!-- <collision>
      <origin xyz="0 0 0" rpy="0 0 0" />
      <geometry>
        <mesh filename="../meshes/L_ankle_pitch_link.STL" />
      </geometry>
    </collision> -->
  </link>
  <joint name="left_ankle_pitch_joint" type="revolute">
    <origin xyz="0.0349999999999996 -0.0241 -0.279999999999994" rpy="0 0 0" />
    <parent link="left_knee_link" />
    <child link="left_ankle_pitch_link" />
    <axis xyz="0 1 0" />
    <limit lower="-0.87267" upper="0.5236" effort="50" velocity="37"/>
  </joint>
  <link name="left_ankle_roll_link">
    <inertial>
      <origin xyz="-0.006 0 -0.046" rpy="0 0 0" />
      <mass value="0.625" />
      <inertia ixx="0.002" ixy="0" ixz="0" iyy="0.003" iyz="0" izz="0.001" />
    </inertial>
    <visual>
      <origin xyz="0 0 0" rpy="0 0 0" />
      <geometry>
        <mesh filename="../meshes/L_ankle_roll_link.STL" />
      </geometry>
      <material name="">
        <color rgba="0.752941176470588 0.752941176470588 0.752941176470588 1" />
      </material>
    </visual>
    <collision>
      <origin xyz="0 0 0" rpy="0 0 0" />
      <geometry>
        <mesh filename="../meshes/L_ankle_roll_link.STL" />
      </geometry>
    </collision>
  </link>
  <joint name="left_ankle_roll_joint" type="revolute">
    <origin xyz="0.015 -0.0165 0" rpy="0 0 0" />
    <parent link="left_ankle_pitch_link" />
    <child link="left_ankle_roll_link" />
    <axis xyz="1 0 0" />
    <limit lower="-0.2618" upper="0.2618" effort="50" velocity="37"/>
  </joint>
  <link name="right_hip_pitch_link">
    <inertial>
      <origin xyz="0.002 -0.045 0" rpy="0 0 0" />
      <mass value="0.422" />
      <inertia ixx="0.001" ixy="0" ixz="0" iyy="0.001" iyz="0" izz="0.001" />
    </inertial>
    <visual>
      <origin xyz="0 0 0" rpy="0 0 0" />
      <geometry>
        <mesh filename="../meshes/R_hip_pitch_link.STL" />
      </geometry>
      <material name="">
        <color rgba="0.75294 0.75294 0.75294 1" />
      </material>
    </visual>
    <!-- <collision>
      <origin xyz="0 0 0" rpy="0 0 0" />
      <geometry>
        <mesh filename="../meshes/R_hip_pitch_link.STL" />
      </geometry>
    </collision> -->
  </link>
  <joint name="right_hip_pitch_joint" type="revolute">
    <origin xyz="0 -0.079 0" rpy="0 0 0" />
    <parent link="base_link" />
    <child link="right_hip_pitch_link" />
    <axis xyz="0 1 0" />
    <limit lower="-2.62" upper="2.62" effort="88" velocity="32"/>
  </joint>
  <link name="right_hip_roll_link">
    <inertial>
      <origin xyz="-0.032 0.001 -0.078" rpy="0 0 0" />
      <mass value="0.785" />
      <inertia ixx="0.008" ixy="0" ixz="0.002" iyy="0.009" iyz="0" izz="0.002" />
    </inertial>
    <visual>
      <origin xyz="0 0 0" rpy="0 0 0" />
      <geometry>
        <mesh filename="../meshes/R_hip_roll_link.STL" />
      </geometry>
      <material name="">
        <color rgba="0.75294 0.75294 0.75294 1" />
      </material>
    </visual>
    <!-- <collision>
      <origin xyz="0 0 0" rpy="0 0 0" />
      <geometry>
        <mesh filename="../meshes/R_hip_roll_link.STL" />
      </geometry>
    </collision> -->
  </link>
  <joint name="right_hip_roll_joint" type="revolute">
    <origin xyz="0.0366 -0.05 0" rpy="0 0 0" />
    <parent link="right_hip_pitch_link" />
    <child link="right_hip_roll_link" />
    <axis xyz="1 0 0" />
    <limit lower="-3.32" upper="0.17" effort="88" velocity="32"/>
  </joint>
  <link name="right_hip_yaw_link">
    <inertial>
      <origin xyz="-0.019 0.007 -0.08" rpy="0 0 0" />
      <mass value="0.865" />
      <inertia ixx="0.008" ixy="0" ixz="0.002" iyy="0.009" iyz="0" izz="0.002" />
    </inertial>
    <visual>
      <origin xyz="0 0 0" rpy="0 0 0" />
      <geometry>
        <mesh filename="../meshes/R_hip_yaw_link.STL" />
      </geometry>
      <material name="">
        <color rgba="0.75294 0.75294 0.75294 1" />
      </material>
    </visual>
    <!-- <collision>
      <origin xyz="0 0 0" rpy="0 0 0" />
      <geometry>
        <mesh filename="../meshes/R_hip_yaw_link.STL" />
      </geometry>
    </collision> -->
  </link>
  <joint name="right_hip_yaw_joint" type="revolute">
    <origin xyz="-0.0365999999999974 0 -0.156599999999998" rpy="0 0 0" />
    <parent link="right_hip_roll_link" />
    <child link="right_hip_yaw_link" />
    <axis xyz="0 0 1" />
    <limit lower="-2.62" upper="2.62" effort="88" velocity="32"/>
  </joint>
  <link name="right_knee_link">
    <inertial>
      <origin xyz="0.033 0.041 -0.132" rpy="0 0 0" />
      <mass value="2.033" />
      <inertia ixx="0.058" ixy="0" ixz="0" iyy="0.056" iyz="0" izz="0.011" />
    </inertial>
    <visual>
      <origin xyz="0 0 0" rpy="0 0 0" />
      <geometry>
        <mesh filename="../meshes/R_knee_link.STL" />
      </geometry>
      <material name="">
        <color rgba="0.75294 0.75294 0.75294 1" />
      </material>
    </visual>
    <!-- <collision>
      <origin xyz="0 0 0" rpy="0 0 0" />
      <geometry>
        <mesh filename="../meshes/R_knee_link.STL" />
      </geometry>
    </collision> -->
  </link>
  <joint name="right_knee_joint" type="revolute">
    <origin xyz="-0.0349999999999989 -0.0406000000000009 -0.113900000000001" rpy="0 0 0" />
    <parent link="right_hip_yaw_link" />
    <child link="right_knee_link" />
    <axis xyz="0 1 0" />
    <limit lower="-0.17" upper="2.97" effort="139" velocity="20"/>
  </joint>
  <link name="right_ankle_pitch_link">
    <inertial>
      <origin xyz="0 0.017 0" rpy="0 0 0" />
      <mass value="0.056" />
      <inertia ixx="0.0001" ixy="0" ixz="0" iyy="0.0001" iyz="0" izz="0.0001" />
    </inertial>
    <visual>
      <origin xyz="0 0 0" rpy="0 0 0" />
      <geometry>
        <mesh filename="../meshes/R_ankle_pitch_link.STL" />
      </geometry>
      <material name="">
        <color rgba="0.79216 0.81961 0.93333 1" />
      </material>
    </visual>
    <!-- <collision>
      <origin xyz="0 0 0" rpy="0 0 0" />
      <geometry>
        <mesh filename="../meshes/R_ankle_pitch_link.STL" />
      </geometry>
    </collision> -->
  </link>
  <joint name="right_ankle_pitch_joint" type="revolute">
    <origin xyz="0.0349999999999923 0.0241 -0.279999999999994" rpy="0 0 0" />
    <parent link="right_knee_link" />
    <child link="right_ankle_pitch_link" />
    <axis xyz="0 1 0" />
    <limit lower="-0.87267" upper="0.5236" effort="50" velocity="37"/>
  </joint>
  <link name="right_ankle_roll_link">
    <inertial>
      <origin xyz="-0.006 0 -0.046" rpy="0 0 0" />
      <mass value="0.625" />
      <inertia ixx="0.002" ixy="0" ixz="0" iyy="0.003" iyz="0" izz="0.001" />
    </inertial>
    <visual>
      <origin xyz="0 0 0" rpy="0 0 0" />
      <geometry>
        <mesh filename="../meshes/R_ankle_roll_link.STL" />
      </geometry>
      <material name="">
        <color rgba="0.75294 0.75294 0.75294 1" />
      </material>
    </visual>
    <collision>
      <origin xyz="0 0 0" rpy="0 0 0" />
      <geometry>
        <mesh filename="../meshes/R_ankle_roll_link.STL" />
      </geometry>
    </collision>
  </link>
  <joint name="right_ankle_roll_joint" type="revolute">
    <origin xyz="0.015 0.0165 0" rpy="0 0 0" />
    <parent link="right_ankle_pitch_link" />
    <child link="right_ankle_roll_link" />
    <axis xyz="1 0 0" />
    <limit lower="-0.2618" upper="0.2618" effort="50" velocity="37"/>
  </joint>

  <!-- Torso -->
  <link name="waist_yaw_link">
    <inertial>
      <origin xyz="0.001 0 0.032" rpy="0 0 0" />
      <mass value="0.237" />
      <inertia ixx="0.001" ixy="0" ixz="0" iyy="0.001" iyz="0" izz="0.001" />
    </inertial>
    <visual>
      <origin xyz="0 0 0" rpy="0 0 0" />
      <geometry>
        <mesh filename="../meshes/waist_yaw_link.STL" />
      </geometry>
      <material name="">
        <color rgba="0.75294 0.75294 0.75294 1" />
      </material>
    </visual>
    <!-- <collision>
      <origin xyz="0 0 0" rpy="0 0 0" />
      <geometry>
        <mesh filename="../meshes/waist_yaw_link.STL" />
      </geometry>
    </collision> -->
  </link>
  <joint name="waist_yaw_joint" type="fixed">
    <origin xyz="0 0 0.116" rpy="0 0 0" />
    <parent link="base_link" />
    <child link="waist_yaw_link" />
    <axis xyz="0 0 1" />
    <limit lower="-2.79" upper="2.79" effort="88" velocity="32"/>
  </joint>
  <link name="torso_link">
    <inertial>
      <origin xyz="-0.038 0.005 0.127" rpy="0 0 0" />
      <mass value="9.36" />
      <inertia ixx="0.244" ixy="-0.003" ixz="-0.048" iyy="0.246" iyz="0.004" izz="0.07" />
    </inertial>
    <visual>
      <origin xyz="0 0 0" rpy="0 0 0" />
      <geometry>
        <mesh filename="../meshes/waist_roll_link.STL" />
      </geometry>
      <material name="">
        <color rgba="0.752941176470588 0.752941176470588 0.752941176470588 1" />
      </material>
    </visual>
    <collision>
      <origin xyz="0 0 0" rpy="0 0 0" />
      <geometry>
        <mesh filename="../meshes/waist_roll_link.STL" />
      </geometry>
    </collision>
  </link>
  <joint name="waist_roll_joint" type="fixed">
    <origin xyz="0.04 2.1468E-05 0.048" rpy="0 0 0" />
    <parent link="waist_yaw_link" />
    <child link="torso_link" />
    <axis xyz="1 0 0" />
    <limit lower="-0.17" upper="0.17" effort="50" velocity="37"/>
  </joint>
  <link name="left_shoulder_pitch_link">
    <inertial>
      <origin xyz="0.005 0.048 -0.001" rpy="0 0 0" />
      <mass value="0.5784" />
      <inertia ixx="0.002" ixy="0" ixz="0" iyy="0.001" iyz="0" izz="0.002" />
    </inertial>
    <visual>
      <origin xyz="0 0 0" rpy="0 0 0" />
      <geometry>
        <mesh filename="../meshes/L_shoulder_pitch_link.STL" />
      </geometry>
      <material name="">
        <color rgba="0.752941176470588 0.752941176470588 0.752941176470588 1" />
      </material>
    </visual>
    <!-- <collision>
      <origin xyz="0 0 0" rpy="0 0 0" />
      <geometry>
        <mesh filename="../meshes/L_shoulder_pitch_link.STL" />
      </geometry>
    </collision> -->
  </link>

  <!-- IMU -->
  <link name="imu_link"></link>
  <joint name="imu_joint" type="fixed">
    <origin xyz="0 0 -0.0057" rpy="0 0 0"/>
    <parent link="base_link"/>
    <child link="imu_link"/>
  </joint>

  <!-- Arm -->
  <joint name="left_shoulder_pitch_joint" type="revolute">
    <origin xyz="-0.0400000000002751 0.118218532124567 0.214500000000062" rpy="0 0 0" />
    <parent link="torso_link" />
    <child link="left_shoulder_pitch_link" />
    <axis xyz="0 1 0" />
    <limit lower="-2.36" upper="2.36" effort="25" velocity="37"/>
  </joint>
  <link name="left_shoulder_roll_link">
    <inertial>
      <origin xyz="-0.035 0.027 -0.073" rpy="0 0 0" />
      <mass value="0.781" />
      <inertia ixx="0.007" ixy="0" ixz="0" iyy="0.008" iyz="0" izz="0.003" />
    </inertial>
    <visual>
      <origin xyz="0 0 0" rpy="0 0 0" />
      <geometry>
        <mesh filename="../meshes/L_shoulder_roll_link.STL" />
      </geometry>
      <material name="">
        <color rgba="0.752941176470588 0.752941176470588 0.752941176470588 1" />
      </material>
    </visual>
    <!-- <collision>
      <origin xyz="0 0 0" rpy="0 0 0" />
      <geometry>
        <mesh filename="../meshes/L_shoulder_roll_link.STL" />
      </geometry>
    </collision> -->
  </link>
  <joint name="left_shoulder_roll_joint" type="fixed">
    <origin xyz="0.0354999999999784 0.0505000000000042 0" rpy="0 0 0" />
    <parent link="left_shoulder_pitch_link" />
    <child link="left_shoulder_roll_link" />
    <axis xyz="1 0 0" />
    <limit lower="0" upper="2.62" effort="25" velocity="37"/>
  </joint>
  <link name="left_shoulder_yaw_link">
    <inertial>
      <origin xyz="0.014 0.004 -0.054" rpy="0 0 0" />
      <mass value="0.66" />
      <inertia ixx="0.003" ixy="0" ixz="-0.001" iyy="0.003" iyz="0" izz="0.001" />
    </inertial>
    <visual>
      <origin xyz="0 0 0" rpy="0 0 0" />
      <geometry>
        <mesh filename="../meshes/L_shoulder_yaw_link.STL" />
      </geometry>
      <material name="">
        <color rgba="0.752941176470588 0.752941176470588 0.752941176470588 1" />
      </material>
    </visual>
    <!-- <collision>
      <origin xyz="0 0 0" rpy="0 0 0" />
      <geometry>
        <mesh filename="../meshes/L_shoulder_yaw_link.STL" />
      </geometry>
    </collision> -->
  </link>
  <joint name="left_shoulder_yaw_joint" type="fixed">
    <origin xyz="-0.0354999999998045 0.0310000000000109 -0.134500000000048" rpy="0 0 0" />
    <parent link="left_shoulder_roll_link" />
    <child link="left_shoulder_yaw_link" />
    <axis xyz="0 0 1" />
    <limit lower="-2.62" upper="2.62" effort="25" velocity="37"/>
  </joint>
  <link name="left_elbow_link">
    <inertial>
      <origin xyz="-0.018 -0.034 -0.078" rpy="0 0 0" />
      <mass value="0.76" />
      <inertia ixx="0.008" ixy="0" ixz="0.001" iyy="0.007" iyz="0.002" izz="0.002" />
    </inertial>
    <visual>
      <origin xyz="0 0 0" rpy="0 0 0" />
      <geometry>
        <mesh filename="../meshes/L_elbow_link.STL" />
      </geometry>
      <material name="">
        <color rgba="0.752941176470588 0.752941176470588 0.752941176470588 1" />
      </material>
    </visual>
    <!-- <collision>
      <origin xyz="0 0 0" rpy="0 0 0" />
      <geometry>
        <mesh filename="../meshes/L_elbow_link.STL" />
      </geometry>
    </collision> -->
  </link>
  <joint name="left_elbow_joint" type="fixed">
    <origin xyz="0.0200000000000853 0.0339999999999863 -0.0704999999999717" rpy="0 0 0" />
    <parent link="left_shoulder_yaw_link" />
    <child link="left_elbow_link" />
    <axis xyz="0 1 0" />
    <limit lower="-1.0492" upper="1.5708" effort="25" velocity="37"/>
  </joint>
  <link name="right_shoulder_pitch_link">
    <inertial>
      <origin xyz="0.005 -0.048 -0.001" rpy="0 0 0" />
      <mass value="0.5784" />
      <inertia ixx="0.002" ixy="0" ixz="0" iyy="0.001" iyz="0" izz="0.002" />
    </inertial>
    <visual>
      <origin xyz="0 0 0" rpy="0 0 0" />
      <geometry>
        <mesh filename="../meshes/R_shoulder_pitch_link.STL" />
      </geometry>
      <material name="">
        <color rgba="0.752941176470588 0.752941176470588 0.752941176470588 1" />
      </material>
    </visual>
    <!-- <collision>
      <origin xyz="0 0 0" rpy="0 0 0" />
      <geometry>
        <mesh filename="../meshes/R_shoulder_pitch_link.STL" />
      </geometry>
    </collision> -->
  </link>
  <joint name="right_shoulder_pitch_joint" type="revolute">
    <origin xyz="-0.040000000000254 -0.118261467873481 0.214500000000056" rpy="0 0 0" />
    <parent link="torso_link" />
    <child link="right_shoulder_pitch_link" />
    <axis xyz="0 1 0" />
    <limit lower="-2.36" upper="2.36" effort="25" velocity="37"/>
  </joint>
  <link name="right_shoulder_roll_link">
    <inertial>
      <origin xyz="-0.035 -0.027 -0.073" rpy="0 0 0" />
      <mass value="0.781" />
      <inertia ixx="0.007" ixy="0" ixz="0" iyy="0.008" iyz="0" izz="0.003" />
    </inertial>
    <visual>
      <origin xyz="0 0 0" rpy="0 0 0" />
      <geometry>
        <mesh filename="../meshes/R_shoulder_roll_link.STL" />
      </geometry>
      <material name="">
        <color rgba="0.752941176470588 0.752941176470588 0.752941176470588 1" />
      </material>
    </visual>
    <!-- <collision>
      <origin xyz="0 0 0" rpy="0 0 0" />
      <geometry>
        <mesh filename="../meshes/R_shoulder_roll_link.STL" />
      </geometry>
    </collision> -->
  </link>
  <joint name="right_shoulder_roll_joint" type="fixed">
    <origin xyz="0.0354999999999967 -0.0504999999999942 0" rpy="0 0 0" />
    <parent link="right_shoulder_pitch_link" />
    <child link="right_shoulder_roll_link" />
    <axis xyz="1 0 0" />
    <limit lower="-2.62" upper="0" effort="25" velocity="37"/>
  </joint>
  <link name="right_shoulder_yaw_link">
    <inertial>
      <origin xyz="-0.004 -0.014 -0.054" rpy="0 0 0" />
      <mass value="0.66" />
      <inertia ixx="0.003" ixy="0" ixz="0" iyy="0.003" iyz="0.001" izz="0.001" />
    </inertial>
    <visual>
      <origin xyz="0 0 0" rpy="0 0 0" />
      <geometry>
        <mesh filename="../meshes/R_shoulder_yaw_link.STL" />
      </geometry>
      <material name="">
        <color rgba="0.752941176470588 0.752941176470588 0.752941176470588 1" />
      </material>
    </visual>
    <!-- <collision>
      <origin xyz="0 0 0" rpy="0 0 0" />
      <geometry>
        <mesh filename="../meshes/R_shoulder_yaw_link.STL" />
      </geometry>
    </collision> -->
  </link>
  <joint name="right_shoulder_yaw_joint" type="fixed">
    <origin xyz="-0.0354999999998123 -0.030999999999994 -0.13450000000005" rpy="0 0 0" />
    <parent link="right_shoulder_roll_link" />
    <child link="right_shoulder_yaw_link" />
    <axis xyz="0 0 1" />
    <limit lower="-2.62" upper="2.62" effort="25" velocity="37"/>
  </joint>
  <link name="right_elbow_link">
    <inertial>
      <origin xyz="-0.02 0.032 -0.078" rpy="0 0 0" />
      <mass value="0.76" />
      <inertia ixx="0.008" ixy="0" ixz="0.001" iyy="0.007" iyz="-0.002" izz="0.002" />
    </inertial>
    <visual>
      <origin xyz="0 0 0" rpy="0 0 0" />
      <geometry>
        <mesh filename="../meshes/R_elbow_link.STL" />
      </geometry>
      <material name="">
        <color rgba="0.752941176470588 0.752941176470588 0.752941176470588 1" />
      </material>
    </visual>
    <!-- <collision>
      <origin xyz="0 0 0" rpy="0 0 0" />
      <geometry>
        <mesh filename="../meshes/R_elbow_link.STL" />
      </geometry>
    </collision> -->
  </link>
  <joint name="right_elbow_joint" type="fixed">
    <origin xyz="0.0200000000001179 -0.0340000000000086 -0.0704999999999668" rpy="0 0 0" />
    <parent link="right_shoulder_yaw_link" />
    <child link="right_elbow_link" />
    <axis xyz="0 1 0" />
    <limit lower="-1.0492" upper="1.5708" effort="25" velocity="37"/>
  </joint>
</robot>